Workbook

Sheet Instrucciones
A1: Registro y análisis de colas - Audifarma, sede Plaza del Sol
A2: Qué es esto | B2: Libro con DATOS SIMULADOS (generados aleatoriamente) para ilustrar el registro y el cálculo de las estadísticas y los modelos M/M/1, M/M/s y M/G/1 del trabajo. Reemplácelos por mediciones reales de la sede cuando estén disponibles.
A3: Leyenda | B3: Celdas amarillas con letra azul = se llenan con datos o supuestos propios. Celdas sin relleno = fórmulas, no se editan.
A4: Paso 1 - Registro | B4: Una fila por usuario observado: fecha, turno, tipo de trámite, preferencial (S/N), hora del turno, del llamado, inicio y fin de la atención, módulo. Las columnas K (espera), L (atención) y M (franja) se calculan solas.
A5: Paso 2 - Llegadas | B5: Cuente los turnos emitidos por franja y por día. Edite los rótulos de las franjas según el horario real y registre los módulos habilitados (s) en cada franja.
A6: Paso 3 - Intervalos_5min | B6: Opcional: llegadas en intervalos consecutivos de 5 minutos para comparar media y varianza (indicio de Poisson).
A7: Paso 4 - Resumen | B7: Lea las estadísticas de servicio y espera. En la sección C escriba λ y s del escenario y compare los tres modelos.
A8: Supuestos ajustables | B8: El umbral 'Crítico' (ρ ≥ 0,85, hoja Llegadas) y el umbral de espera de 15 min (hoja Resumen) son convenciones de trabajo, no normas. Cámbielos si su director define otros.
A9: Límites | B9: Las pruebas de bondad de ajuste (chi-cuadrado, Kolmogorov-Smirnov) y la simulación de eventos discretos no están en este libro; se hacen aparte (por ejemplo, en Python con SciPy).
A10: Capacidad | B10: Registro admite 1000 usuarios, Llegadas 15 días y 10 franjas, Intervalos_5min 300 intervalos, y la sección C hasta 12 módulos.
A12: Ejemplo de FORMATO (no es un dato real, no se usa en los cálculos)
A13: N.º | B13: Fecha | C13: Turno | D13: Tipo de trámite | E13: Pref. (S/N) | F13: Hora turno | G13: Hora llamado | H13: Inicio atención | I13: Fin atención | J13: Módulo
A14: 1 | B14: 46023 | C14: D-001 | D14: Dispensación | E14: N | F14: 0.33333333 | G14: 0.33680556 | H14: 0.3369213 | I14: 0.33888889 | J14: 1

Sheet Registro
A1: Registro de observación - tiempos en los módulos de atención
A2: Celdas amarillas: se llenan con las observaciones reales. Columnas K, L y M se calculan solas. Horas en formato hh:mm:ss.
A3: N.º | B3: Fecha | C3: Turno | D3: Tipo de trámite | E3: Pref. (S/N) | F3: Hora turno | G3: Hora llamado | H3: Inicio atención | I3: Fin atención | J3: Módulo | K3: Espera en fila (min) | L3: Duración atención (min) | M3: Franja (hora de llegada)
A4: 1 | B4: 46083 | C4: P-002 | D4: Pendientes | E4: N | F4: 0.29476254 | G4: 0.29476254 | H4: 0.29478569 | I4: 0.29916069 | J4: 2 | K4: =IF(AND(ISNUMBER(F4),ISNUMBER(G4)),(G4-F4)*1440,"") | L4: =IF(AND(ISNUMBER(H4),ISNUMBER(I4)),(I4-H4)*1440,"") | M4: =IF(ISNUMBER(F4),HOUR(F4),"")
A5: 2 | B5: 46083 | C5: D-012 | D5: Dispensación | E5: S | F5: 0.29988896 | G5: 0.30019078 | H5: 0.3002255 | I5: 0.30347782 | J5: 2 | K5: =IF(AND(ISNUMBER(F5),ISNUMBER(G5)),(G5-F5)*1440,"") | L5: =IF(AND(ISNUMBER(H5),ISNUMBER(I5)),(I5-H5)*1440,"") | M5: =IF(ISNUMBER(F5),HOUR(F5),"")
A6: 3 | B6: 46083 | C6: V-007 | D6: Turno virtual | E6: N | F6: 0.30380455 | G6: 0.30853378 | H6: 0.30855693 | I6: 0.31021202 | J6: 3 | K6: =IF(AND(ISNUMBER(F6),ISNUMBER(G6)),(G6-F6)*1440,"") | L6: =IF(AND(ISNUMBER(H6),ISNUMBER(I6)),(I6-H6)*1440,"") | M6: =IF(ISNUMBER(F6),HOUR(F6),"")
A7: 4 | B7: 46083 | C7: P-012 | D7: Pendientes | E7: N | F7: 0.30415398 | G7: 0.31127969 | H7: 0.31132598 | I7: 0.31339774 | J7: 1 | K7: =IF(AND(ISNUMBER(F7),ISNUMBER(G7)),(G7-F7)*1440,"") | L7: =IF(AND(ISNUMBER(H7),ISNUMBER(I7)),(I7-H7)*1440,"") | M7: =IF(ISNUMBER(F7),HOUR(F7),"")
A8: 5 | B8: 46083 | C8: D-022 | D8: Dispensación | E8: N | F8: 0.316126 | G8: 0.32034289 | H8: 0.32038919 | I8: 0.32317854 | J8: 4 | K8: =IF(AND(ISNUMBER(F8),ISNUMBER(G8)),(G8-F8)*1440,"") | L8: =IF(AND(ISNUMBER(H8),ISNUMBER(I8)),(I8-H8)*1440,"") | M8: =IF(ISNUMBER(F8),HOUR(F8),"")
A9: 6 | B9: 46083 | C9: V-017 | D9: Turno virtual | E9: N | F9: 0.31899504 | G9: 0.32512298 | H9: 0.32513456 | I9: 0.32690539 | J9: 4 | K9: =IF(AND(ISNUMBER(F9),ISNUMBER(G9)),(G9-F9)*1440,"") | L9: =IF(AND(ISNUMBER(H9),ISNUMBER(I9)),(I9-H9)*1440,"") | M9: =IF(ISNUMBER(F9),HOUR(F9),"")
A10: 7 | B10: 46083 | C10: P-038 | D10: Pendientes | E10: N | F10: 0.34274933 | G10: 0.35941532 | H10: 0.35945004 | I10: 0.36138291 | J10: 2 | K10: =IF(AND(ISNUMBER(F10),ISNUMBER(G10)),(G10-F10)*1440,"") | L10: =IF(AND(ISNUMBER(H10),ISNUMBER(I10)),(I10-H10)*1440,"") | M10: =IF(ISNUMBER(F10),HOUR(F10),"")
A11: 8 | B11: 46083 | C11: D-054 | D11: Dispensación | E11: N | F11: 0.34477044 | G11: 0.36067854 | H11: 0.36069011 | I11: 0.36378039 | J11: 4 | K11: =IF(AND(ISNUMBER(F11),ISNUMBER(G11)),(G11-F11)*1440,"") | L11: =IF(AND(ISNUMBER(H11),ISNUMBER(I11)),(I11-H11)*1440,"") | M11: =IF(ISNUMBER(F11),HOUR(F11),"")
A12: 9 | B12: 46083 | C12: P-044 | D12: Pendientes | E12: N | F12: 0.34955278 | G12: 0.37007504 | H12: 0.37008661 | I12: 0.37196161 | J12: 2 | K12: =IF(AND(ISNUMBER(F12),ISNUMBER(G12)),(G12-F12)*1440,"") | L12: =IF(AND(ISNUMBER(H12),ISNUMBER(I12)),(I12-H12)*1440,"") | M12: =IF(ISNUMBER(F12),HOUR(F12),"")
A13: 10 | B13: 46083 | C13: P-052 | D13: Pendientes | E13: S | F13: 0.35793365 | G13: 0.35913848 | H13: 0.35918478 | I13: 0.36080515 | J13: 1 | K13: =IF(AND(ISNUMBER(F13),ISNUMBER(G13)),(G13-F13)*1440,"") | L13: =IF(AND(ISNUMBER(H13),ISNUMBER(I13)),(I13-H13)*1440,"") | M13: =IF(ISNUMBER(F13),HOUR(F13),"")
A14: 11 | B14: 46083 | C14: P-058 | D14: Pendientes | E14: N | F14: 0.36709497 | G14: 0.38740143 | H14: 0.38742457 | I14: 0.38969309 | J14: 2 | K14: =IF(AND(ISNUMBER(F14),ISNUMBER(G14)),(G14-F14)*1440,"") | L14: =IF(AND(ISNUMBER(H14),ISNUMBER(I14)),(I14-H14)*1440,"") | M14: =IF(ISNUMBER(F14),HOUR(F14),"")
A15: 12 | B15: 46083 | C15: P-060 | D15: Pendientes | E15: N | F15: 0.36948422 | G15: 0.38950885 | H15: 0.38955515 | I15: 0.39191626 | J15: 1 | K15: =IF(AND(ISNUMBER(F15),ISNUMBER(G15)),(G15-F15)*1440,"") | L15: =IF(AND(ISNUMBER(H15),ISNUMBER(I15)),(I15-H15)*1440,"") | M15: =IF(ISNUMBER(F15),HOUR(F15),"")
... A423: 420 | B423: 46094 | C423: D-277 | D423: Dispensación | E423: N | F423: 0.69261884 | G423: 0.69261884 | H423: 0.69263042 | I423: 0.69337116 | J423: 3 | K423: =IF(AND(ISNUMBER(F423),ISNUMBER(G423)),(G423-F423)*1440,"") | L423: =IF(AND(ISNUMBER(H423),ISNUMBER(I423)),(I423-H423)*1440,"") | M423: =IF(ISNUMBER(F423),HOUR(F423),"")
K424: =IF(AND(ISNUMBER(F424),ISNUMBER(G424)),(G424-F424)*1440,"") | L424: =IF(AND(ISNUMBER(H424),ISNUMBER(I424)),(I424-H424)*1440,"") | M424: =IF(ISNUMBER(F424),HOUR(F424),"")
K425: =IF(AND(ISNUMBER(F425),ISNUMBER(G425)),(G425-F425)*1440,"") | L425: =IF(AND(ISNUMBER(H425),ISNUMBER(I425)),(I425-H425)*1440,"") | M425: =IF(ISNUMBER(F425),HOUR(F425),"")
K426: =IF(AND(ISNUMBER(F426),ISNUMBER(G426)),(G426-F426)*1440,"") | L426: =IF(AND(ISNUMBER(H426),ISNUMBER(I426)),(I426-H426)*1440,"") | M426: =IF(ISNUMBER(F426),HOUR(F426),"")
K427: =IF(AND(ISNUMBER(F427),ISNUMBER(G427)),(G427-F427)*1440,"") | L427: =IF(AND(ISNUMBER(H427),ISNUMBER(I427)),(I427-H427)*1440,"") | M427: =IF(ISNUMBER(F427),HOUR(F427),"")
K428: =IF(AND(ISNUMBER(F428),ISNUMBER(G428)),(G428-F428)*1440,"") | L428: =IF(AND(ISNUMBER(H428),ISNUMBER(I428)),(I428-H428)*1440,"") | M428: =IF(ISNUMBER(F428),HOUR(F428),"")
K429: =IF(AND(ISNUMBER(F429),ISNUMBER(G429)),(G429-F429)*1440,"") | L429: =IF(AND(ISNUMBER(H429),ISNUMBER(I429)),(I429-H429)*1440,"") | M429: =IF(ISNUMBER(F429),HOUR(F429),"")
K430: =IF(AND(ISNUMBER(F430),ISNUMBER(G430)),(G430-F430)*1440,"") | L430: =IF(AND(ISNUMBER(H430),ISNUMBER(I430)),(I430-H430)*1440,"") | M430: =IF(ISNUMBER(F430),HOUR(F430),"")
K431: =IF(AND(ISNUMBER(F431),ISNUMBER(G431)),(G431-F431)*1440,"") | L431: =IF(AND(ISNUMBER(H431),ISNUMBER(I431)),(I431-H431)*1440,"") | M431: =IF(ISNUMBER(F431),HOUR(F431),"")
K432: =IF(AND(ISNUMBER(F432),ISNUMBER(G432)),(G432-F432)*1440,"") | L432: =IF(AND(ISNUMBER(H432),ISNUMBER(I432)),(I432-H432)*1440,"") | M432: =IF(ISNUMBER(F432),HOUR(F432),"")
K433: =IF(AND(ISNUMBER(F433),ISNUMBER(G433)),(G433-F433)*1440,"") | L433: =IF(AND(ISNUMBER(H433),ISNUMBER(I433)),(I433-H433)*1440,"") | M433: =IF(ISNUMBER(F433),HOUR(F433),"")
K434: =IF(AND(ISNUMBER(F434),ISNUMBER(G434)),(G434-F434)*1440,"") | L434: =IF(AND(ISNUMBER(H434),ISNUMBER(I434)),(I434-H434)*1440,"") | M434: =IF(ISNUMBER(F434),HOUR(F434),"")
K435: =IF(AND(ISNUMBER(F435),ISNUMBER(G435)),(G435-F435)*1440,"") | L435: =IF(AND(ISNUMBER(H435),ISNUMBER(I435)),(I435-H435)*1440,"") | M435: =IF(ISNUMBER(F435),HOUR(F435),"")
... K1003: =IF(AND(ISNUMBER(F1003),ISNUMBER(G1003)),(G1003-F1003)*1440,"") | L1003: =IF(AND(ISNUMBER(H1003),ISNUMBER(I1003)),(I1003-H1003)*1440,"") | M1003: =IF(ISNUMBER(F1003),HOUR(F1003),"")

Sheet Llegadas
A1: Llegadas (turnos emitidos) por día y franja horaria
A2: Umbral de condición 'Crítico' (ρ ≥) | D2: 0.85 | E2: Convención ajustable (supuesto de trabajo, no es una norma). ρ ≥ 1 siempre es 'Inestable'.
A3: Edite los rótulos de las franjas (fila 5) según el horario real de la sede. Cuente cada franja en el mismo día.
A4: Día | B4: 7:00-8:00 | C4: 8:00-9:00 | D4: 9:00-10:00 | E4: 10:00-11:00 | F4: 11:00-12:00 | G4: 12:00-13:00 | H4: 13:00-14:00 | I4: 14:00-15:00 | J4: 15:00-16:00 | K4: 16:00-17:00 | L4: Total
A5: Día 1 | B5: 95 | C5: 106 | D5: 83 | E5: 71 | F5: 48 | G5: 50 | H5: 45 | I5: 56 | J5: 58 | K5: 40 | L5: =IF(COUNT(B5:K5)=0,"",SUM(B5:K5))
A6: Día 2 | B6: 94 | C6: 94 | D6: 78 | E6: 69 | F6: 54 | G6: 37 | H6: 45 | I6: 74 | J6: 66 | K6: 33 | L6: =IF(COUNT(B6:K6)=0,"",SUM(B6:K6))
A7: Día 3 | B7: 83 | C7: 93 | D7: 101 | E7: 98 | F7: 54 | G7: 32 | H7: 48 | I7: 63 | J7: 48 | K7: 24 | L7: =IF(COUNT(B7:K7)=0,"",SUM(B7:K7))
A8: Día 4 | B8: 97 | C8: 111 | D8: 88 | E8: 70 | F8: 58 | G8: 43 | H8: 52 | I8: 70 | J8: 52 | K8: 34 | L8: =IF(COUNT(B8:K8)=0,"",SUM(B8:K8))
A9: Día 5 | B9: 89 | C9: 93 | D9: 109 | E9: 84 | F9: 64 | G9: 40 | H9: 47 | I9: 72 | J9: 55 | K9: 44 | L9: =IF(COUNT(B9:K9)=0,"",SUM(B9:K9))
A10: Día 6 | B10: 92 | C10: 105 | D10: 72 | E10: 77 | F10: 57 | G10: 36 | H10: 52 | I10: 67 | J10: 56 | K10: 36 | L10: =IF(COUNT(B10:K10)=0,"",SUM(B10:K10))
A11: Día 7 | B11: 95 | C11: 97 | D11: 93 | E11: 67 | F11: 53 | G11: 40 | H11: 51 | I11: 71 | J11: 55 | K11: 31 | L11: =IF(COUNT(B11:K11)=0,"",SUM(B11:K11))
A12: Día 8 | B12: 82 | C12: 90 | D12: 79 | E12: 61 | F12: 46 | G12: 38 | H12: 46 | I12: 73 | J12: 60 | K12: 32 | L12: =IF(COUNT(B12:K12)=0,"",SUM(B12:K12))
A13: Día 9 | B13: 90 | C13: 106 | D13: 105 | E13: 67 | F13: 70 | G13: 49 | H13: 52 | I13: 65 | J13: 60 | K13: 32 | L13: =IF(COUNT(B13:K13)=0,"",SUM(B13:K13))
A14: Día 10 | B14: 81 | C14: 106 | D14: 83 | E14: 72 | F14: 47 | G14: 38 | H14: 49 | I14: 63 | J14: 63 | K14: 41 | L14: =IF(COUNT(B14:K14)=0,"",SUM(B14:K14))
A15: Día 11 | L15: =IF(COUNT(B15:K15)=0,"",SUM(B15:K15))
A16: Día 12 | L16: =IF(COUNT(B16:K16)=0,"",SUM(B16:K16))
A17: Día 13 | L17: =IF(COUNT(B17:K17)=0,"",SUM(B17:K17))
A18: Día 14 | L18: =IF(COUNT(B18:K18)=0,"",SUM(B18:K18))
A19: Día 15 | L19: =IF(COUNT(B19:K19)=0,"",SUM(B19:K19))
A21: Promedio λ (usuarios/h) | B21: =IF(COUNT(B5:B19)=0,"",AVERAGE(B5:B19)) | C21: =IF(COUNT(C5:C19)=0,"",AVERAGE(C5:C19)) | D21: =IF(COUNT(D5:D19)=0,"",AVERAGE(D5:D19)) | E21: =IF(COUNT(E5:E19)=0,"",AVERAGE(E5:E19)) | F21: =IF(COUNT(F5:F19)=0,"",AVERAGE(F5:F19)) | G21: =IF(COUNT(G5:G19)=0,"",AVERAGE(G5:G19)) | H21: =IF(COUNT(H5:H19)=0,"",AVERAGE(H5:H19)) | I21: =IF(COUNT(I5:I19)=0,"",AVERAGE(I5:I19)) | ... K21: =IF(COUNT(K5:K19)=0,"",AVERAGE(K5:K19)) | L21: =IF(COUNT(B21:K21)=0,"",SUM(B21:K21))
A22: Desviación estándar | B22: =IF(COUNT(B5:B19)<2,"",STDEV(B5:B19)) | C22: =IF(COUNT(C5:C19)<2,"",STDEV(C5:C19)) | D22: =IF(COUNT(D5:D19)<2,"",STDEV(D5:D19)) | E22: =IF(COUNT(E5:E19)<2,"",STDEV(E5:E19)) | F22: =IF(COUNT(F5:F19)<2,"",STDEV(F5:F19)) | G22: =IF(COUNT(G5:G19)<2,"",STDEV(G5:G19)) | H22: =IF(COUNT(H5:H19)<2,"",STDEV(H5:H19)) | I22: =IF(COUNT(I5:I19)<2,"",STDEV(I5:I19)) | ... L22: =IF(COUNT(L5:L19)<2,"",STDEV(L5:L19))
A23: Coeficiente de variación | B23: =IF(OR(B21="",B22=""),"",IF(B21=0,"",B22/B21)) | C23: =IF(OR(C21="",C22=""),"",IF(C21=0,"",C22/C21)) | D23: =IF(OR(D21="",D22=""),"",IF(D21=0,"",D22/D21)) | E23: =IF(OR(E21="",E22=""),"",IF(E21=0,"",E22/E21)) | F23: =IF(OR(F21="",F22=""),"",IF(F21=0,"",F22/F21)) | G23: =IF(OR(G21="",G22=""),"",IF(G21=0,"",G22/G21)) | H23: =IF(OR(H21="",H22=""),"",IF(H21=0,"",H22/H21)) | I23: =IF(OR(I21="",I22=""),"",IF(I21=0,"",I22/I21)) | ... L23: =IF(OR(L21="",L22=""),"",IF(L21=0,"",L22/L21))
A24: Módulos habilitados (s) | B24: 4 | C24: 4 | D24: 4 | E24: 4 | F24: 4 | G24: 3 | H24: 3 | I24: 4 | J24: 4 | K24: 4
A25: Capacidad s·μ (usuarios/h) | B25: =IF(AND(ISNUMBER(B24),ISNUMBER(Resumen!$B$15)),B24*Resumen!$B$15,"") | C25: =IF(AND(ISNUMBER(C24),ISNUMBER(Resumen!$B$15)),C24*Resumen!$B$15,"") | D25: =IF(AND(ISNUMBER(D24),ISNUMBER(Resumen!$B$15)),D24*Resumen!$B$15,"") | E25: =IF(AND(ISNUMBER(E24),ISNUMBER(Resumen!$B$15)),E24*Resumen!$B$15,"") | F25: =IF(AND(ISNUMBER(F24),ISNUMBER(Resumen!$B$15)),F24*Resumen!$B$15,"") | G25: =IF(AND(ISNUMBER(G24),ISNUMBER(Resumen!$B$15)),G24*Resumen!$B$15,"") | H25: =IF(AND(ISNUMBER(H24),ISNUMBER(Resumen!$B$15)),H24*Resumen!$B$15,"") | I25: =IF(AND(ISNUMBER(I24),ISNUMBER(Resumen!$B$15)),I24*Resumen!$B$15,"") | ... K25: =IF(AND(ISNUMBER(K24),ISNUMBER(Resumen!$B$15)),K24*Resumen!$B$15,"")
A26: ρ = λ/(s·μ) | B26: =IF(AND(ISNUMBER(B21),ISNUMBER(B25)),IF(B25=0,"",B21/B25),"") | C26: =IF(AND(ISNUMBER(C21),ISNUMBER(C25)),IF(C25=0,"",C21/C25),"") | D26: =IF(AND(ISNUMBER(D21),ISNUMBER(D25)),IF(D25=0,"",D21/D25),"") | E26: =IF(AND(ISNUMBER(E21),ISNUMBER(E25)),IF(E25=0,"",E21/E25),"") | F26: =IF(AND(ISNUMBER(F21),ISNUMBER(F25)),IF(F25=0,"",F21/F25),"") | G26: =IF(AND(ISNUMBER(G21),ISNUMBER(G25)),IF(G25=0,"",G21/G25),"") | H26: =IF(AND(ISNUMBER(H21),ISNUMBER(H25)),IF(H25=0,"",H21/H25),"") | I26: =IF(AND(ISNUMBER(I21),ISNUMBER(I25)),IF(I25=0,"",I21/I25),"") | ... K26: =IF(AND(ISNUMBER(K21),ISNUMBER(K25)),IF(K25=0,"",K21/K25),"")
A27: Condición | B27: =IF(ISNUMBER(B26),IF(B26>=1,"Inestable",IF(B26>=$D$2,"Crítico","Estable")),"") | C27: =IF(ISNUMBER(C26),IF(C26>=1,"Inestable",IF(C26>=$D$2,"Crítico","Estable")),"") | D27: =IF(ISNUMBER(D26),IF(D26>=1,"Inestable",IF(D26>=$D$2,"Crítico","Estable")),"") | E27: =IF(ISNUMBER(E26),IF(E26>=1,"Inestable",IF(E26>=$D$2,"Crítico","Estable")),"") | F27: =IF(ISNUMBER(F26),IF(F26>=1,"Inestable",IF(F26>=$D$2,"Crítico","Estable")),"") | G27: =IF(ISNUMBER(G26),IF(G26>=1,"Inestable",IF(G26>=$D$2,"Crítico","Estable")),"") | H27: =IF(ISNUMBER(H26),IF(H26>=1,"Inestable",IF(H26>=$D$2,"Crítico","Estable")),"") | I27: =IF(ISNUMBER(I26),IF(I26>=1,"Inestable",IF(I26>=$D$2,"Crítico","Estable")),"") | ... K27: =IF(ISNUMBER(K26),IF(K26>=1,"Inestable",IF(K26>=$D$2,"Crítico","Estable")),"")
A29: Nota: la columna Total (fila 22) es la suma de los λ promedio, es decir, usuarios por día; la fila 23 de esa columna es la desviación entre días.

Sheet Intervalos_5min
A1: Llegadas por intervalo de 5 minutos (verificación del supuesto de Poisson)
A2: Llegadas en intervalos consecutivos de 5 minutos de la franja 9:00-10:00 (12 intervalos por día, días 1 a 10).
A3: Intervalo | B3: Llegadas | D3: Número de intervalos | E3: =COUNT(B4:B303)
A4: 1 | B4: 7 | D4: Media | E4: =IF(E3=0,"",AVERAGE(B4:B303))
A5: 2 | B5: 5 | D5: Varianza | E5: =IF(E3<2,"",VAR(B4:B303))
A6: 3 | B6: 7 | D6: Varianza / media | E6: =IF(OR(E4="",E5=""),"",IF(E4=0,"",E5/E4))
A7: 4 | B7: 7
A8: 5 | B8: 5 | D8: En una distribución de Poisson, media y varianza son iguales (cociente ≈ 1). Es un indicio, no una prueba:
A9: 6 | B9: 9 | D9: la prueba chi-cuadrado y la de Kolmogorov-Smirnov se hacen aparte (por ejemplo, con SciPy).
A10: 7 | B10: 10
A11: 8 | B11: 7
A12: 9 | B12: 8
A13: 10 | B13: 4
A14: 11 | B14: 5
A15: 12 | B15: 9
A16: 13 | B16: 4
A17: 14 | B17: 8
A18: 15 | B18: 8
A19: 16 | B19: 6
A20: 17 | B20: 8
A21: 18 | B21: 10
... A123: 120 | B123: 8

Sheet Entre_llegadas
A1: Tiempos entre llegadas consecutivas - franja 9:00-10:00 (días 1 a 10)
A2: Se toma la hora de emisión de cada turno dentro de la franja y se calcula la diferencia con el turno anterior del mismo día.
A3: N.º | B3: Fecha | C3: Hora llegada | D3: Hora llegada anterior | E3: Tiempo entre llegadas (min) | G3: Número de tiempos | H3: =COUNT(E4:E884)
A4: 1 | B4: 46083 | C4: 0.37608829 | D4: 0.37566332 | E4: =(C4-D4)*1440 | G4: Media (min) | H4: =AVERAGE(E4:E884)
A5: 2 | B5: 46083 | C5: 0.3762401 | D5: 0.37608829 | E5: =(C5-D5)*1440 | G5: Desviación estándar (min) | H5: =STDEV(E4:E884)
A6: 3 | B6: 46083 | C6: 0.3762402 | D6: 0.3762401 | E6: =(C6-D6)*1440 | G6: Coeficiente de variación | H6: =H5/H4
A7: 4 | B7: 46083 | C7: 0.37692956 | D7: 0.3762402 | E7: =(C7-D7)*1440 | G7: Tasa implícita (usuarios/h) = 60/media | H7: =60/H4
A8: 5 | B8: 46083 | C8: 0.37808005 | D8: 0.37692956 | E8: =(C8-D8)*1440
A9: 6 | B9: 46083 | C9: 0.37828135 | D9: 0.37808005 | E9: =(C9-D9)*1440 | G9: En la distribución exponencial la media y la desviación estándar son iguales (CV ≈ 1).
A10: 7 | B10: 46083 | C10: 0.37896698 | D10: 0.37828135 | E10: =(C10-D10)*1440
A11: 8 | B11: 46083 | C11: 0.37989637 | D11: 0.37896698 | E11: =(C11-D11)*1440
A12: 9 | B12: 46083 | C12: 0.38026271 | D12: 0.37989637 | E12: =(C12-D12)*1440
A13: 10 | B13: 46083 | C13: 0.38129236 | D13: 0.38026271 | E13: =(C13-D13)*1440
A14: 11 | B14: 46083 | C14: 0.38179035 | D14: 0.38129236 | E14: =(C14-D14)*1440
A15: 12 | B15: 46083 | C15: 0.38212913 | D15: 0.38179035 | E15: =(C15-D15)*1440
A16: 13 | B16: 46083 | C16: 0.3826188 | D16: 0.38212913 | E16: =(C16-D16)*1440
A17: 14 | B17: 46083 | C17: 0.38303696 | D17: 0.3826188 | E17: =(C17-D17)*1440
A18: 15 | B18: 46083 | C18: 0.38417313 | D18: 0.38303696 | E18: =(C18-D18)*1440
A19: 16 | B19: 46083 | C19: 0.38440114 | D19: 0.38417313 | E19: =(C19-D19)*1440
A20: 17 | B20: 46083 | C20: 0.38495874 | D20: 0.38440114 | E20: =(C20-D20)*1440
A21: 18 | B21: 46083 | C21: 0.38538517 | D21: 0.38495874 | E21: =(C21-D21)*1440
... A884: 881 | B884: 46094 | C884: 0.41581651 | D884: 0.41576067 | E884: =(C884-D884)*1440

Sheet Resumen
A1: Resumen estadístico y modelos de colas
A2: A. Tiempo de servicio (min) - columna L del Registro
A3: Tamaño de muestra (n) | B3: =COUNT(Registro!$L$4:$L$1003)
A4: Media (min) | B4: =IF($B$3=0,"",AVERAGE(Registro!$L$4:$L$1003))
A5: Mediana (min) | B5: =IF($B$3=0,"",MEDIAN(Registro!$L$4:$L$1003))
A6: Desviación estándar (min) | B6: =IF($B$3<2,"",STDEV(Registro!$L$4:$L$1003))
A7: Coeficiente de variación | B7: =IF(OR(B6="",B4=""),"",IF(B4=0,"",B6/B4))
A8: Primer cuartil | B8: =IF($B$3=0,"",QUARTILE(Registro!$L$4:$L$1003,1))
A9: Tercer cuartil | B9: =IF($B$3=0,"",QUARTILE(Registro!$L$4:$L$1003,3))
A10: Percentil 90 | B10: =IF($B$3=0,"",PERCENTILE(Registro!$L$4:$L$1003,0.9))
A11: Mínimo | B11: =IF($B$3=0,"",MIN(Registro!$L$4:$L$1003))
A12: Máximo | B12: =IF($B$3=0,"",MAX(Registro!$L$4:$L$1003))
A13: Asimetría | B13: =IF($B$3<3,"",SKEW(Registro!$L$4:$L$1003))
A14: Curtosis (exceso) | B14: =IF($B$3<4,"",KURT(Registro!$L$4:$L$1003))
A15: Tasa de servicio μ (usuarios/h) = 60 / media | B15: =IF(B4="","",IF(B4=0,"",60/B4))
A17: B. Espera en fila (min) - turno a llamado, columna K del Registro
A18: Tamaño de muestra (n) | B18: =COUNT(Registro!$K$4:$K$1003)
A19: Media (min) | B19: =IF($B$18=0,"",AVERAGE(Registro!$K$4:$K$1003))
A20: Mediana (min) | B20: =IF($B$18=0,"",MEDIAN(Registro!$K$4:$K$1003))
A21: Percentil 90 (min) | B21: =IF($B$18=0,"",PERCENTILE(Registro!$K$4:$K$1003,0.9))
A22: Percentil 95 (min) | B22: =IF($B$18=0,"",PERCENTILE(Registro!$K$4:$K$1003,0.95))
A23: Máximo (min) | B23: =IF($B$18=0,"",MAX(Registro!$K$4:$K$1003))
A24: Umbral de espera (min) | B24: 15 | C24: Valor ajustable (supuesto de trabajo).
A25: % de usuarios que esperan más del umbral | B25: =IF($B$18=0,"",COUNTIF(Registro!$K$4:$K$1003,">"&$B$24)/$B$18)
A27: C. Medidas de desempeño según el modelo (un escenario a la vez)
A28: Escriba λ y s del escenario. μ, σ y la media salen de la sección A. Si ρ ≥ 1 no hay estado estable y los modelos no se calculan.
A29: λ del sistema (usuarios/h) | B29: 67.4
A30: Módulos habilitados (s), de 1 a 12 | B30: 4
A31: μ por módulo (usuarios/h) | B31: =B15
A32: σ del servicio (min) | B32: =B6
A33: Media del servicio (min) | B33: =B4
A34: ρ = λ/(s·μ) | B34: =IF(AND(ISNUMBER(B29),ISNUMBER(B30),ISNUMBER(B31)),IF(B30*B31=0,"",B29/(B30*B31)),"")
A35: Estado | B35: =IF(ISNUMBER(B34),IF(B34>=1,"Inestable (ρ ≥ 1)","Estable"),"")
A36: Cs² = (σ / media)² | B36: =IF(AND(ISNUMBER(B32),ISNUMBER(B33)),IF(B33<>0,(B32/B33)^2,""),"")
A37: a = λ/μ (carga ofrecida) | B37: =IF(AND(ISNUMBER(B29),ISNUMBER(B31)),IF(B31=0,"",B29/B31),"")
A39: Indicador | B39: M/M/1 (filas independientes) | C39: M/G/1 (filas independientes) | D39: M/M/s (fila única) | E39: M/M/s corregido (Allen-Cunneen)
A40: λ de la cola (usuarios/h) | B40: =IF(ISNUMBER($B$34),IF($B$34<1,$B$29/$B$30,""),"") | C40: =IF(AND(ISNUMBER($B$34),ISNUMBER($B$36)),IF($B$34<1,$B$29/$B$30,""),"") | D40: =IF(ISNUMBER($B$34),IF($B$34<1,$B$29,""),"") | E40: =IF(ISNUMBER($B$34),IF($B$34<1,$B$29,""),"")
A41: Factor de utilización ρ | B41: =IF(ISNUMBER($B$34),IF($B$34<1,$B$34,""),"") | C41: =IF(ISNUMBER($B$34),IF($B$34<1,$B$34,""),"") | D41: =IF(ISNUMBER($B$34),IF($B$34<1,$B$34,""),"") | E41: =IF(ISNUMBER($B$34),IF($B$34<1,$B$34,""),"")
A42: Probabilidad de sistema vacío P₀ | B42: =IF(ISNUMBER($B$34),IF($B$34<1,1-$B$34,""),"") | C42: =IF(ISNUMBER($B$34),IF($B$34<1,1-$B$34,""),"") | D42: =IF(ISNUMBER($B$34),IF($B$34<1,1/(SUM($B$51:$B$62)+$B$37^$B$30/(FACT($B$30)*(1-$B$34))),""),"") | E42: =IF(ISNUMBER(D42),D42,"")
A43: Lq: usuarios en cola (total sede) | B43: =IF(ISNUMBER($B$34),IF($B$34<1,$B$30*$B$34^2/(1-$B$34),""),"") | C43: =IF(AND(ISNUMBER($B$34),ISNUMBER($B$36)),IF($B$34<1,$B$30*(($B$29/$B$30)^2*($B$32/60)^2+$B$34^2)/(2*(1-$B$34)),""),"") | D43: =IF(ISNUMBER($B$34),IF($B$34<1,D42*$B$37^$B$30*$B$34/(FACT($B$30)*(1-$B$34)^2),""),"") | E43: =IF(ISNUMBER(E45),E45*$B$29/60,"")
...
